<mujoco model="pr2_donbot">
  <compiler angle="radian" autolimits="true" />
  <size njmax="5000" nconmax="1000" />
  <asset>
    <mesh name="base_without_wheels" file="pr2_donbot/meshes/iai_donbot/base_without_wheels.stl" />
    <mesh name="base" file="pr2_donbot/meshes/iai_donbot/base.stl" />
    <mesh name="shoulder" file="pr2_donbot/meshes/iai_donbot/shoulder.stl" />
    <mesh name="upperarm" file="pr2_donbot/meshes/iai_donbot/upperarm.stl" />
    <mesh name="forearm" file="pr2_donbot/meshes/iai_donbot/forearm.stl" />
    <mesh name="wrist1" file="pr2_donbot/meshes/iai_donbot/wrist1.stl" />
    <mesh name="wrist2" file="pr2_donbot/meshes/iai_donbot/wrist2.stl" />
    <mesh name="wrist3" file="pr2_donbot/meshes/iai_donbot/wrist3.stl" />
    <mesh name="adapter_plate_iso50_kms40_weiss" file="pr2_donbot/meshes/iai_donbot/adapter_plate_iso50_kms40_weiss.stl" scale="0.001 0.001 0.001" />
    <mesh name="kms40_simple" file="pr2_donbot/meshes/iai_donbot/kms40_simple.stl" scale="0.001 0.001 0.001" />
    <mesh name="adapter_kms40_fwk050" file="pr2_donbot/meshes/iai_donbot/adapter_kms40_fwk050.stl" scale="0.001 0.001 0.001" />
    <mesh name="fwk_fwa_050_simple" file="pr2_donbot/meshes/iai_donbot/fwk_fwa_050_simple.stl" scale="0.001 0.001 0.001" />
    <mesh name="adapter_fwa050_wsg50" file="pr2_donbot/meshes/iai_donbot/adapter_fwa050_wsg50.stl" scale="0.001 0.001 0.001" />
    <mesh name="WSG50_110" file="pr2_donbot/meshes/iai_donbot/WSG50_110.stl" />
    <mesh name="GUIDE_WSG50_110" file="pr2_donbot/meshes/iai_donbot/GUIDE_WSG50_110.stl" scale="0.001 0.001 0.001" />
    <mesh name="WSG-FMF" file="pr2_donbot/meshes/iai_donbot/WSG-FMF.stl" scale="0.001 0.001 0.001" />
    <mesh name="refills_camera_holder_and_camera" file="pr2_donbot/meshes/iai_donbot/refills_camera_holder_and_camera.stl" />

    <mesh name="base_L" file="pr2_donbot/meshes/iai_pr2/base_L.stl" />
    <mesh name="caster_L" file="pr2_donbot/meshes/iai_pr2/caster_L.stl" />
    <mesh name="torso_lift_L" file="pr2_donbot/meshes/iai_pr2/torso_lift_L.stl" />
    <mesh name="head_pan_L" file="pr2_donbot/meshes/iai_pr2/head_pan_L.stl" />
    <mesh name="head_tilt_L" file="pr2_donbot/meshes/iai_pr2/head_tilt_L.stl" />
    <mesh name="tilting_hokuyo_L" file="pr2_donbot/meshes/iai_pr2/tilting_hokuyo_L.stl" />
    <mesh name="shoulder_pan" file="pr2_donbot/meshes/iai_pr2/shoulder_pan.stl" />
    <mesh name="shoulder_lift" file="pr2_donbot/meshes/iai_pr2/shoulder_lift.stl" />
    <mesh name="upper_arm_roll_L" file="pr2_donbot/meshes/iai_pr2/upper_arm_roll_L.stl" />
    <mesh name="upper_arm" file="pr2_donbot/meshes/iai_pr2/upper_arm.stl" />
    <mesh name="forearm_roll_L" file="pr2_donbot/meshes/iai_pr2/forearm_roll_L.stl" />
    <mesh name="elbow_flex" file="pr2_donbot/meshes/iai_pr2/elbow_flex.stl" />
    <mesh name="forearm_L" file="pr2_donbot/meshes/iai_pr2/forearm.stl" />
    <mesh name="wrist_flex" file="pr2_donbot/meshes/iai_pr2/wrist_flex.stl" />
    <mesh name="wrist_roll_L" file="pr2_donbot/meshes/iai_pr2/wrist_roll_L.stl" />
    <mesh name="gripper_palm" file="pr2_donbot/meshes/iai_pr2/gripper_palm.stl" />
    <mesh name="l_finger" file="pr2_donbot/meshes/iai_pr2/l_finger.stl" />
    <mesh name="l_finger_tip" file="pr2_donbot/meshes/iai_pr2/l_finger_tip.stl" />
  </asset>

  <worldbody>
    <body name="iai_donbot" pos="0 0 0">
      <geom size="0.0005 0.0005 0.0005" type="box" />
      <geom pos="0.25525 0.225 0.1616" type="mesh" rgba="0.792157 0.819608 0.933333 1" mesh="base_without_wheels" />
      <geom size="0.3 0.2765 0.01" pos="-0.04475 -0.005 0.6216" type="box" />
      <geom pos="-0.26975 -0.199 0.6316" quat="0 0 0 1" type="mesh" rgba="0.7 0.7 0.7 1" mesh="base" />
      <geom size="0.06 0.2 0.225" pos="-0.40475 0 0.3866" type="box" rgba="1 1 1 1" />
      <geom size="0.075 0.15 0.19" pos="0.33025 0 0.3516" type="box" rgba="1 1 1 1" />
      <geom size="0.035 0.035 0.05" pos="0.22025 0.2235 0.6816" type="box" rgba="1 1 0 1" />
      <geom size="0.125 0.07 0.025" pos="0.30525 0 0.5666" quat="0.987701 0 -0.156356 0" type="box" rgba="1 1 1 1" />
      <geom size="0.16 0.03 0.12" pos="0.09525 -0.3105 0.5416" type="box" rgba="1 1 1 1" />
      <body name="wheel_front_left" pos="0.38525 0.315 0.1016">
        <inertial pos="0 0 0" mass="2" diaginertia="0.01 0.01 0.01" />
        <joint name="wheel_front_left_joint" pos="0 0 0" axis="0 1 0" range="-1000 1000" />
        <geom size="0.105 0.04" quat="0.707107 0.707107 0 0" type="cylinder" rgba="0.792157 0.819608 0.933333 1" />
      </body>
      <body name="wheel_back_left" pos="-0.39275 0.315 0.1016">
        <inertial pos="0 0 0" mass="2" diaginertia="0.01 0.01 0.01" />
        <joint name="wheel_back_left_joint" pos="0 0 0" axis="0 1 0" range="-1000 1000" />
        <geom size="0.105 0.04" quat="0.707107 0.707107 0 0" type="cylinder" rgba="0.792157 0.819608 0.933333 1" />
      </body>
      <body name="wheel_front_right" pos="0.38525 -0.32 0.1016">
        <inertial pos="0 0 0" mass="2" diaginertia="0.01 0.01 0.01" />
        <joint name="wheel_front_right_joint" pos="0 0 0" axis="0 1 0" range="-1000 1000" />
        <geom size="0.105 0.04" quat="0.707107 0.707107 0 0" type="cylinder" rgba="0.792157 0.819608 0.933333 1" />
      </body>
      <body name="wheel_back_right" pos="-0.39275 -0.32 0.1016">
        <inertial pos="0 0 0" mass="2" diaginertia="0.01 0.01 0.01" />
        <joint name="wheel_back_right_joint" pos="0 0 0" axis="0 1 0" range="-1000 1000" />
        <geom size="0.105 0.04" quat="0.707107 0.707107 0 0" type="cylinder" rgba="0.792157 0.819608 0.933333 1" />
      </body>
      <body name="ur5_shoulder_link" pos="-0.26975 -0.199 0.720759" quat="0 0 0 1">
        <inertial pos="0 0 0" mass="3.7" diaginertia="0.0149724 0.0149724 0.0104063" />
        <joint name="ur5_shoulder_pan_joint" pos="0 0 0" axis="0 0 1" range="-6.28319 6.28319" />
        <geom quat="0 0 0 1" type="mesh" rgba="0.7 0.7 0.7 1" mesh="shoulder" />
        <body name="ur5_upper_arm_link" pos="0 0 0" quat="0.707107 0.707107 0 0">
          <inertial pos="-0.2125 0 0.136" quat="0.707107 0 0.707107 0" mass="8.393" diaginertia="0.133886 0.133886 0.0151074" />
          <joint name="ur5_shoulder_lift_joint" pos="0 0 0" axis="0 0 1" range="-6.28319 6.28319" />
          <geom pos="0 0 0.136" quat="0.5 0.5 -0.5 -0.5" type="mesh" rgba="0.7 0.7 0.7 1" mesh="upperarm" />
          <body name="ur5_forearm_link" pos="-0.425 0 0">
            <inertial pos="-0.2125 0 0.0165" quat="0.707107 0 0.707107 0" mass="2.275" diaginertia="0.0312168 0.0312168 0.004095" />
            <joint name="ur5_elbow_joint" pos="0 0 0" axis="0 0 1" range="-3.14159 3.14159" />
            <geom pos="0 0 0.0165" quat="0.5 0.5 -0.5 -0.5" type="mesh" rgba="0.7 0.7 0.7 1" mesh="forearm" />
            <body name="ur5_wrist_1_link" pos="-0.39225 0 0.10915">
              <inertial pos="0 0 0" quat="0.5 0.5 -0.5 0.5" mass="1.219" diaginertia="0.00342844 0.00262426 0.00262426" />
              <joint name="ur5_wrist_1_joint" pos="0 0 0" axis="0 0 1" range="-6.28319 6.28319" />
              <geom pos="0 0 -0.093" quat="0.707107 0.707107 0 0" type="mesh" rgba="0.7 0.7 0.7 1" mesh="wrist1" />
              <body name="ur5_wrist_2_link" pos="0 -0.09465 -1.9413e-11" quat="0.707107 0.707107 0 0">
                <inertial pos="0 0 0" quat="0.5 0.5 -0.5 0.5" mass="1.219" diaginertia="0.0021942 0.00178515 0.00178515" />
                <joint name="ur5_wrist_2_joint" pos="0 0 0" axis="0 0 1" range="-6.28319 6.28319" />
                <geom pos="0 0 -0.095" type="mesh" rgba="0.7 0.7 0.7 1" mesh="wrist2" />
                <body name="ur5_wrist_3_link" pos="0 0.0823 -1.688e-11" quat="0.707107 -0.707107 0 0">
                  <inertial pos="0.0177497 -0.00353721 0.0573026" quat="0.544566 0.273974 0.152579 0.777886" mass="1.67643" diaginertia="1.00446 1.00433 1.0019" />
                  <joint name="ur5_wrist_3_joint" pos="0 0 0" axis="0 0 1" range="-6.28319 6.28319" />
                  <geom pos="0 0 -0.0823" quat="0.707107 0.707107 0 0" type="mesh" rgba="0.7 0.7 0.7 1" mesh="wrist3" />
                  <geom size="0.005 0.005 0.005" pos="0 0 -0.01" quat="0.5 0.5 -0.5 0.5" type="box" />
                  <geom quat="-0.707107 0 0 0.707107" type="mesh" rgba="0.7 0.7 0.7 1" mesh="adapter_plate_iso50_kms40_weiss" />
                  <geom pos="0 0 0.016" quat="-0.707107 0 0 0.707107" type="mesh" rgba="0.7 0.7 0.7 1" mesh="kms40_simple" />
                  <geom pos="0 0 0.043" quat="-0.707107 0 0 0.707107" type="mesh" rgba="0.7 0.7 0.7 1" mesh="adapter_kms40_fwk050" />
                  <geom pos="0 0 0.053" quat="-0.707107 0 0 0.707107" type="mesh" rgba="0.7 0.7 0.7 1" mesh="fwk_fwa_050_simple" />
                  <geom pos="0 0 0.0671" quat="-0.707107 0 0 0.707107" type="mesh" rgba="0.7 0.7 0.7 1" mesh="adapter_fwa050_wsg50" />
                  <geom pos="0 0 0.0771" quat="-0.707107 0 0 -0.707107" type="mesh" mesh="WSG50_110" />
                  <geom pos="0 0 0.0771" quat="0.707107 0 0 -0.707107" type="mesh" rgba="0.56 0.67 0.67 1" mesh="refills_camera_holder_and_camera" />
                  <geom size="0.04 0.04" pos="0 0 0.038" quat="-0.707107 0 0 0.707107" type="cylinder" />
                  <body name="gripper_gripper_left_link" pos="0 0 0.0771" quat="-0.707107 0 0 -0.707107">
                    <inertial pos="-0.000539792 0 0.0285709" quat="0.999908 0 -0.013597 0" mass="0.2312" diaginertia="2.0005 2.0005 2" />
                    <joint name="gripper_base_gripper_left_joint" pos="0 0 0" axis="1 0 0" type="slide" range="-0.055 -0.0027" damping="100" frictionloss="100" />
                    <geom type="mesh" rgba="0 0 0 1" mesh="GUIDE_WSG50_110" />
                    <geom pos="0 0 0.023" type="mesh" rgba="0 0 0 1" mesh="WSG-FMF" />
                    <geom size="0.004 0.015 0.065" pos="-0.004 0 0.138" type="box" rgba="0.56 0.67 0.67 1" />
                    <body name="gripper_gripper_right_link" pos="0 0 0" quat="1.32679e-06 0 0 1">
                      <inertial pos="-0.000539792 0 0.0285709" quat="0.999908 0 -0.013597 0" mass="0.2312" diaginertia="2.0005 2.0005 2" />
                      <joint name="gripper_joint" pos="0 0 0" axis="-1 0 0" type="slide" range="0.0065 0.109" damping="100" frictionloss="100" />
                      <geom type="mesh" rgba="0 0 0 1" mesh="GUIDE_WSG50_110" />
                      <geom pos="0 0 0.023" type="mesh" rgba="0 0 0 1" mesh="WSG-FMF" />
                      <geom size="0.004 0.015 0.065" pos="-0.004 0 0.138" type="box" rgba="0.56 0.67 0.67 1" />
                    </body>
                  </body>
                </body>
              </body>
            </body>
          </body>
        </body>
      </body>
    </body>

    <body name="iai_pr2" pos="0 2 0">
      <geom size="0.0005 0.0005 0.0005" pos="0 0 0.071" type="box" rgba="1 1 1 1" />
      <geom pos="0 0 0.051" type="mesh" rgba="1 1 1 1" mesh="base_L" />
      <geom size="0.025 0.185 0.15" pos="-0.29 0 0.851" type="box" rgba="0.1 0.1 0.1 1" />
      <body name="fl_caster_rotation_link" pos="0.2246 0.2246 0.0792">
        <inertial pos="0 0 0.07" quat="0.589921 -0.182261 -0.205712 0.759247" mass="3.47308" diaginertia="0.0153925 0.0125446 0.0114568" />
        <joint name="fl_caster_rotation_joint" pos="0 0 0" axis="0 0 1" damping="1" />
        <geom type="mesh" mesh="caster_L" />
        <body name="fl_caster_l_wheel_link" pos="0 0.049 0">
          <inertial pos="0 0 0" quat="0.589921 -0.182261 -0.205712 0.759247" mass="0.44036" diaginertia="0.0153925 0.0125446 0.0114568" />
          <joint name="fl_caster_l_wheel_joint" pos="0 0 0" axis="0 1 0" damping="1" />
          <geom size="0.074792 0.017" quat="0.707107 0.707107 0 0" type="cylinder" />
        </body>
        <body name="fl_caster_r_wheel_link" pos="0 -0.049 0">
          <inertial pos="0 0 0" quat="0.589921 -0.182261 -0.205712 0.759247" mass="0.44036" diaginertia="0.0153925 0.0125446 0.0114568" />
          <joint name="fl_caster_r_wheel_joint" pos="0 0 0" axis="0 1 0" damping="1" />
          <geom size="0.074792 0.017" quat="0.707107 0.707107 0 0" type="cylinder" />
        </body>
      </body>
      <body name="fr_caster_rotation_link" pos="0.2246 -0.2246 0.0792">
        <inertial pos="0 0 0.07" quat="0.589921 -0.182261 -0.205712 0.759247" mass="3.47308" diaginertia="0.0153925 0.0125446 0.0114568" />
        <joint name="fr_caster_rotation_joint" pos="0 0 0" axis="0 0 1" damping="1" />
        <geom type="mesh" mesh="caster_L" />
        <body name="fr_caster_l_wheel_link" pos="0 0.049 0">
          <inertial pos="0 0 0" quat="0.589921 -0.182261 -0.205712 0.759247" mass="0.44036" diaginertia="0.0153925 0.0125446 0.0114568" />
          <joint name="fr_caster_l_wheel_joint" pos="0 0 0" axis="0 1 0" damping="1" />
          <geom size="0.074792 0.017" quat="0.707107 0.707107 0 0" type="cylinder" />
        </body>
        <body name="fr_caster_r_wheel_link" pos="0 -0.049 0">
          <inertial pos="0 0 0" quat="0.589921 -0.182261 -0.205712 0.759247" mass="0.44036" diaginertia="0.0153925 0.0125446 0.0114568" />
          <joint name="fr_caster_r_wheel_joint" pos="0 0 0" axis="0 1 0" damping="1" />
          <geom size="0.074792 0.017" quat="0.707107 0.707107 0 0" type="cylinder" />
        </body>
      </body>
      <body name="bl_caster_rotation_link" pos="-0.2246 0.2246 0.0792">
        <inertial pos="0 0 0.07" quat="0.589921 -0.182261 -0.205712 0.759247" mass="3.47308" diaginertia="0.0153925 0.0125446 0.0114568" />
        <joint name="bl_caster_rotation_joint" pos="0 0 0" axis="0 0 1" damping="1" />
        <geom type="mesh" mesh="caster_L" />
        <body name="bl_caster_l_wheel_link" pos="0 0.049 0">
          <inertial pos="0 0 0" quat="0.589921 -0.182261 -0.205712 0.759247" mass="0.44036" diaginertia="0.0153925 0.0125446 0.0114568" />
          <joint name="bl_caster_l_wheel_joint" pos="0 0 0" axis="0 1 0" damping="1" />
          <geom size="0.074792 0.017" quat="0.707107 0.707107 0 0" type="cylinder" />
        </body>
        <body name="bl_caster_r_wheel_link" pos="0 -0.049 0">
          <inertial pos="0 0 0" quat="0.589921 -0.182261 -0.205712 0.759247" mass="0.44036" diaginertia="0.0153925 0.0125446 0.0114568" />
          <joint name="bl_caster_r_wheel_joint" pos="0 0 0" axis="0 1 0" damping="1" />
          <geom size="0.074792 0.017" quat="0.707107 0.707107 0 0" type="cylinder" />
        </body>
      </body>
      <body name="br_caster_rotation_link" pos="-0.2246 -0.2246 0.0792">
        <inertial pos="0 0 0.07" quat="0.589921 -0.182261 -0.205712 0.759247" mass="3.47308" diaginertia="0.0153925 0.0125446 0.0114568" />
        <joint name="br_caster_rotation_joint" pos="0 0 0" axis="0 0 1" damping="1" />
        <geom type="mesh" mesh="caster_L" />
        <body name="br_caster_l_wheel_link" pos="0 0.049 0">
          <inertial pos="0 0 0" quat="0.589921 -0.182261 -0.205712 0.759247" mass="0.44036" diaginertia="0.0153925 0.0125446 0.0114568" />
          <joint name="br_caster_l_wheel_joint" pos="0 0 0" axis="0 1 0" damping="1" />
          <geom size="0.074792 0.017" quat="0.707107 0.707107 0 0" type="cylinder" />
        </body>
        <body name="br_caster_r_wheel_link" pos="0 -0.049 0">
          <inertial pos="0 0 0" quat="0.589921 -0.182261 -0.205712 0.759247" mass="0.44036" diaginertia="0.0153925 0.0125446 0.0114568" />
          <joint name="br_caster_r_wheel_joint" pos="0 0 0" axis="0 1 0" damping="1" />
          <geom size="0.074792 0.017" quat="0.707107 0.707107 0 0" type="cylinder" />
        </body>
      </body>
      <body name="torso_lift_link" pos="-0.05 0 0.790675">
        <inertial pos="-0.0994987 -4.1071e-06 -0.0867639" quat="0.999302 0.00758941 0.0364107 0.00350465" mass="36.449" diaginertia="2.8145 2.53392 0.52639" />
        <joint name="torso_lift_joint" pos="0 0 0" axis="0 0 1" type="slide" range="0 0.33" damping="20000" />
        <geom type="mesh" rgba="0.9 0.9 0.9 1" mesh="torso_lift_L" />
        <body name="head_pan_link" pos="-0.01707 0 0.38145">
          <inertial pos="0.010907 0.031693 0.090507" quat="-0.0432724 0.73785 -0.0944754 0.666918" mass="6.339" diaginertia="0.0583935 0.0461226 0.0321798" />
          <joint name="head_pan_joint" pos="0 0 0" axis="0 0 1" range="-3.007 3.007" damping="0.5" />
          <geom type="mesh" rgba="0 0 0.8 1" mesh="head_pan_L" />
          <body name="head_tilt_link" pos="0.068 0 0">
            <inertial pos="-0.00537338 -0.0145955 0.0727506" quat="0.126957 0.770263 0.146252 0.607607" mass="5.319" diaginertia="0.158274 0.155945 0.115394" />
            <joint name="head_tilt_joint" pos="0 0 0" axis="0 1 0" range="-0.471238 1.39626" damping="10" />
            <geom type="mesh" rgba="0 0.8 0 1" mesh="head_tilt_L" />
            <geom size="0.005 0.005 0.005" pos="0.0232 0 0.0645" type="box" rgba="0 0 0.8 1" />
            <geom size="0.0005" pos="-0.1148 0 0.1555" />
            <geom size="0.0005" pos="-0.147067 0.0125 0.291953" />
            <geom size="0.0005" pos="-0.158342 -0.0120956 0.28185" quat="0.999829 -0.00321238 -0.0181378 -0.00180656" />
            <geom size="0.0005" pos="-0.161257 0.0125 0.244421" />
          </body>
        </body>
        <body name="laser_tilt_mount_link" pos="0.09893 0 0.227">
          <inertial pos="-0.00113408 0.00166718 -0.00706863" quat="0.993882 0.079111 -0.0456728 0.062079" mass="0.592" diaginertia="0.00130297 0.00108878 0.000886143" />
          <joint name="laser_tilt_mount_joint" pos="0 0 0" axis="0 1 0" range="-0.7854 1.48353" damping="0.008" />
          <geom type="mesh" rgba="0.8 0 0 1" mesh="tilting_hokuyo_L" />
        </body>
        <body name="r_shoulder_pan_link" pos="0 -0.188 0">
          <inertial pos="-0.001201 0.024513 -0.098231" quat="0.927482 -0.0876561 0.0740595 -0.355821" mass="25.7993" diaginertia="0.934201 0.837701 0.242033" />
          <joint name="r_shoulder_pan_joint" pos="0 0 0" axis="0 0 1" range="-2.2854 0.714602" damping="10" />
          <geom type="mesh" rgba="0 0 0.8 1" mesh="shoulder_pan" />
          <body name="r_shoulder_lift_link" pos="0.1 0 0">
            <inertial pos="0.02195 -0.02664 -0.03127" quat="0.791779 0.478014 0.238985 0.295762" mass="2.74988" diaginertia="0.0261874 0.0207302 0.0151681" />
            <joint name="r_shoulder_lift_joint" pos="0 0 0" axis="0 1 0" range="-0.5236 1.3963" damping="10" />
            <geom type="mesh" rgba="0.7 0.7 0.7 1" mesh="shoulder_lift" />
            <body name="r_upper_arm_roll_link" pos="0 0 0">
              <inertial pos="0.210482 -0.015945 -0.000196731" quat="-0.0448642 0.697702 -0.0890666 0.709413" mass="6.11769" diaginertia="0.0906678 0.0894595 0.025134" />
              <joint name="r_upper_arm_roll_joint" pos="0 0 0" axis="1 0 0" range="-3.9 0.8" damping="0.1" />
              <geom type="mesh" mesh="upper_arm_roll_L" />
              <geom type="mesh" rgba="0 0.8 0 1" mesh="upper_arm" />
              <body name="r_elbow_flex_link" pos="0.4 0 0">
                <inertial pos="0.01014 0.00032 -0.01211" quat="0.308784 0.646797 0.639077 0.279083" mass="1.90327" diaginertia="0.00441852 0.00396477 0.00308977" />
                <joint name="r_elbow_flex_joint" pos="0 0 0" axis="0 1 0" range="-2.3213 0" damping="1" />
                <geom type="mesh" rgba="0.7 0.7 0.7 1" mesh="elbow_flex" />
                <body name="r_forearm_roll_link" pos="0 0 0">
                  <inertial pos="0.180743 -0.000154674 -0.0086052" quat="-0.00113739 0.72623 -0.00398207 0.687439" mass="2.68968" diaginertia="0.0310593 0.029524 0.0146289" />
                  <joint name="r_forearm_roll_joint" pos="0 0 0" axis="1 0 0" damping="0.1" />
                  <geom type="mesh" mesh="forearm_roll_L" />
                  <geom type="mesh" rgba="0.7 0.7 0.7 1" mesh="forearm_L" />
                  <body name="r_wrist_flex_link" pos="0.321 0 0">
                    <inertial pos="-0.00157 0 -0.00075" quat="0.695976 0.696411 -0.12356 0.123942" mass="0.61402" diaginertia="0.000652771 0.000643391 0.000198244" />
                    <joint name="r_wrist_flex_joint" pos="0 0 0" axis="0 1 0" range="-2.18 0" damping="0.1" />
                    <geom type="mesh" rgba="0.7 0.7 0.7 1" mesh="wrist_flex" />
                    <body name="r_wrist_roll_link" pos="0 0 0">
                      <inertial pos="0.0564084 0.000451403 -0.00101353" quat="-0.010742 0.709375 0.00817429 0.704702" mass="0.68107" diaginertia="0.012243 0.0120554 0.0113518" />
                      <joint name="r_wrist_roll_joint" pos="0 0 0" axis="1 0 0" damping="0.1" />
                      <geom type="mesh" mesh="wrist_roll_L" />
                      <geom type="mesh" rgba="0.8 0 0 1" mesh="gripper_palm" />
                      <geom size="0.0005 0.0005 0.0005" type="box" />
                      <body name="r_gripper_motor_slider_link" pos="0.16828 0 0">
                        <inertial pos="0 0 0" mass="0.01" diaginertia="0.001 0.001 0.001" />
                        <joint name="r_gripper_motor_slider_joint" pos="0 0 0" axis="1 0 0" type="slide" range="-0.1 0.1" />
                        <body name="r_gripper_motor_screw_link" pos="0 0 0">
                          <inertial pos="0 0 0" mass="0.01" diaginertia="0.0001 0.0001 0.0001" />
                          <joint name="r_gripper_motor_screw_joint" pos="0 0 0" axis="0 1 0" damping="0.0001" />
                        </body>
                      </body>
                      <body name="r_gripper_l_finger_link" pos="0.07691 0.01 0">
                        <inertial pos="0.03598 0.0173 -0.00164" quat="0.57444 0.429111 0.518782 0.465562" mass="0.17126" diaginertia="0.00019774 0.000181336 7.66239e-05" />
                        <joint name="r_gripper_l_finger_joint" pos="0 0 0" axis="0 0 1" range="0 0.548" damping="0.02" />
                        <geom type="mesh" rgba="0.7 0.7 0.7 1" mesh="l_finger" />
                        <body name="r_gripper_l_finger_tip_link" pos="0.09137 0.00495 0">
                          <inertial pos="0.00423 0.00284 0" quat="0.249588 0.661594 -0.249588 0.661594" mass="0.04419" diaginertia="1.54177e-05 1.50049e-05 3.23624e-06" />
                          <joint name="r_gripper_l_finger_tip_joint" pos="0 0 0" axis="0 0 -1" range="0 0.548" damping="0.001" />
                          <geom type="mesh" rgba="0 0.8 0 1" mesh="l_finger_tip" />
                        </body>
                      </body>
                      <body name="r_gripper_r_finger_link" pos="0.07691 -0.01 0">
                        <inertial pos="0.03576 -0.01736 -0.00095" quat="0.474684 0.510909 0.446353 0.560727" mass="0.17389" diaginertia="0.000198903 0.00018134 7.66847e-05" />
                        <joint name="r_gripper_r_finger_joint" pos="0 0 0" axis="0 0 -1" range="0 0.548" damping="0.02" />
                        <geom quat="0 1 0 0" type="mesh" rgba="0.7 0.7 0.7 1" mesh="l_finger" />
                        <body name="r_gripper_r_finger_tip_link" pos="0.09137 -0.00495 0">
                          <inertial pos="0.00423 -0.00284 0" quat="-0.249588 0.661594 0.249588 0.661594" mass="0.04419" diaginertia="1.54177e-05 1.50049e-05 3.23624e-06" />
                          <joint name="r_gripper_r_finger_tip_joint" pos="0 0 0" axis="0 0 1" range="0 0.548" damping="0.001" />
                          <geom quat="0 1 0 0" type="mesh" rgba="0 0.8 0 1" mesh="l_finger_tip" />
                        </body>
                      </body>
                    </body>
                  </body>
                </body>
              </body>
            </body>
          </body>
        </body>
        <body name="l_shoulder_pan_link" pos="0 0.188 0">
          <inertial pos="-0.001201 0.024513 -0.098231" quat="0.927482 -0.0876561 0.0740595 -0.355821" mass="25.7993" diaginertia="0.934201 0.837701 0.242033" />
          <joint name="l_shoulder_pan_joint" pos="0 0 0" axis="0 0 1" range="-0.714602 2.2854" damping="10" />
          <geom type="mesh" rgba="0 0 0.8 1" mesh="shoulder_pan" />
          <body name="l_shoulder_lift_link" pos="0.1 0 0">
            <inertial pos="0.02195 -0.02664 -0.03127" quat="0.791779 0.478014 0.238985 0.295762" mass="2.74988" diaginertia="0.0261874 0.0207302 0.0151681" />
            <joint name="l_shoulder_lift_joint" pos="0 0 0" axis="0 1 0" range="-0.5236 1.3963" damping="10" />
            <geom type="mesh" rgba="0.7 0.7 0.7 1" mesh="shoulder_lift" />
            <body name="l_upper_arm_roll_link" pos="0 0 0">
              <inertial pos="0.210551 0.016309 -0.000560683" quat="-0.091509 0.708532 -0.0511954 0.697845" mass="6.11769" diaginertia="0.0906036 0.0894141 0.0251091" />
              <joint name="l_upper_arm_roll_joint" pos="0 0 0" axis="1 0 0" range="-0.8 3.9" damping="0.1" />
              <geom type="mesh" mesh="upper_arm_roll_L" />
              <geom type="mesh" rgba="0 0.8 0 1" mesh="upper_arm" />
              <body name="l_elbow_flex_link" pos="0.4 0 0">
                <inertial pos="0.01014 0.00032 -0.01211" quat="0.308784 0.646797 0.639077 0.279083" mass="1.90327" diaginertia="0.00441852 0.00396477 0.00308977" />
                <joint name="l_elbow_flex_joint" pos="0 0 0" axis="0 1 0" range="-2.3213 0" damping="1" />
                <geom type="mesh" rgba="0.7 0.7 0.7 1" mesh="elbow_flex" />
                <body name="l_forearm_roll_link" pos="0 0 0">
                  <inertial pos="0.180761 -0.000189143 -0.00861532" quat="-0.000343669 0.726167 -0.00296181 0.687512" mass="2.68968" diaginertia="0.0310553 0.0295176 0.0146273" />
                  <joint name="l_forearm_roll_joint" pos="0 0 0" axis="1 0 0" damping="0.1" />
                  <geom type="mesh" mesh="forearm_roll_L" />
                  <geom type="mesh" rgba="0.7 0.7 0.7 1" mesh="forearm_L" />
                  <body name="l_wrist_flex_link" pos="0.321 0 0">
                    <inertial pos="-0.00157 0 -0.00075" quat="0.695976 0.696411 -0.12356 0.123942" mass="0.61402" diaginertia="0.000652771 0.000643391 0.000198244" />
                    <joint name="l_wrist_flex_joint" pos="0 0 0" axis="0 1 0" range="-2.18 0" damping="0.1" />
                    <geom type="mesh" rgba="0.7 0.7 0.7 1" mesh="wrist_flex" />
                    <body name="l_wrist_roll_link" pos="0 0 0">
                      <inertial pos="0.083774 0.000416757 -0.000935737" quat="-0.00714845 0.709843 0.00452806 0.704309" mass="0.737689" diaginertia="0.0128462 0.0126584 0.0113663" />
                      <joint name="l_wrist_roll_joint" pos="0 0 0" axis="1 0 0" damping="0.1" />
                      <geom type="mesh" mesh="wrist_roll_L" />
                      <geom size="0.0225 0.0178" pos="0.0476 0 0" quat="0.579228 -0.40558 -0.579228 0.40558" type="cylinder" rgba="0.7 0.7 0.7 1" />
                      <geom pos="0.0356 0 0" type="mesh" rgba="0.8 0 0 1" mesh="gripper_palm" />
                      <geom size="0.0005 0.0005 0.0005" pos="0.0356 0 0" type="box" />
                      <body name="l_gripper_motor_slider_link" pos="0.20388 0 0">
                        <inertial pos="0 0 0" mass="0.01" diaginertia="0.001 0.001 0.001" />
                        <joint name="l_gripper_motor_slider_joint" pos="0 0 0" axis="1 0 0" type="slide" range="-0.1 0.1" />
                        <body name="l_gripper_motor_screw_link" pos="0 0 0">
                          <inertial pos="0 0 0" mass="0.01" diaginertia="0.0001 0.0001 0.0001" />
                          <joint name="l_gripper_motor_screw_joint" pos="0 0 0" axis="0 1 0" damping="0.0001" />
                        </body>
                      </body>
                      <body name="l_gripper_l_finger_link" pos="0.11251 0.01 0">
                        <inertial pos="0.03598 0.0173 -0.00164" quat="0.57444 0.429111 0.518782 0.465562" mass="0.17126" diaginertia="0.00019774 0.000181336 7.66239e-05" />
                        <joint name="l_gripper_l_finger_joint" pos="0 0 0" axis="0 0 1" range="0 0.548" damping="0.02" />
                        <geom type="mesh" rgba="0.7 0.7 0.7 1" mesh="l_finger" />
                        <body name="l_gripper_l_finger_tip_link" pos="0.09137 0.00495 0">
                          <inertial pos="0.00423 0.00284 0" quat="0.249588 0.661594 -0.249588 0.661594" mass="0.04419" diaginertia="1.54177e-05 1.50049e-05 3.23624e-06" />
                          <joint name="l_gripper_l_finger_tip_joint" pos="0 0 0" axis="0 0 -1" range="0 0.548" damping="0.001" />
                          <geom type="mesh" rgba="0 0.8 0 1" mesh="l_finger_tip" />
                        </body>
                      </body>
                      <body name="l_gripper_r_finger_link" pos="0.11251 -0.01 0">
                        <inertial pos="0.03576 -0.01736 -0.00095" quat="0.474684 0.510909 0.446353 0.560727" mass="0.17389" diaginertia="0.000198903 0.00018134 7.66847e-05" />
                        <joint name="l_gripper_r_finger_joint" pos="0 0 0" axis="0 0 -1" range="0 0.548" damping="0.02" />
                        <geom quat="0 1 0 0" type="mesh" rgba="0.7 0.7 0.7 1" mesh="l_finger" />
                        <body name="l_gripper_r_finger_tip_link" pos="0.09137 -0.00495 0">
                          <inertial pos="0.00423 -0.00284 0" quat="-0.249588 0.661594 0.249588 0.661594" mass="0.04419" diaginertia="1.54177e-05 1.50049e-05 3.23624e-06" />
                          <joint name="l_gripper_r_finger_tip_joint" pos="0 0 0" axis="0 0 1" range="0 0.548" damping="0.001" />
                          <geom quat="0 1 0 0" type="mesh" rgba="0 0.8 0 1" mesh="l_finger_tip" />
                        </body>
                      </body>
                    </body>
                  </body>
                </body>
              </body>
            </body>
          </body>
        </body>
      </body>
      <body name="torso_lift_motor_screw_link" pos="-0.15 0 0.751">
        <inertial pos="0 0 0" mass="1" diaginertia="0.001 0.001 0.001" />
        <joint name="torso_lift_motor_screw_joint" pos="0 0 0" axis="0 0 1" damping="0.0001" />
      </body>
    </body>
  </worldbody>
  <equality>
    <joint joint1="gripper_base_gripper_left_joint" joint2="gripper_joint" polycoef="0.000000 -0.500000  0 0 0" />
  </equality>

  <equality>
    <joint joint1="l_gripper_l_finger_tip_joint" joint2="l_gripper_l_finger_joint" polycoef="0.000000 1.000000  0 0 0" />
    <joint joint1="l_gripper_r_finger_joint" joint2="l_gripper_l_finger_joint" polycoef="0.000000 1.000000  0 0 0" />
    <joint joint1="l_gripper_r_finger_tip_joint" joint2="l_gripper_l_finger_joint" polycoef="0.000000 1.000000  0 0 0" />
    <joint joint1="r_gripper_l_finger_tip_joint" joint2="r_gripper_l_finger_joint" polycoef="0.000000 1.000000  0 0 0" />
    <joint joint1="r_gripper_r_finger_joint" joint2="r_gripper_l_finger_joint" polycoef="0.000000 1.000000  0 0 0" />
    <joint joint1="r_gripper_r_finger_tip_joint" joint2="r_gripper_l_finger_joint" polycoef="0.000000 1.000000  0 0 0" />
  </equality>
</mujoco>